Workbook

Sheet SectorMap
A1: Ticker | B1: Sector | C1: Notes
A2: RELIANCE | B2: Energy | C2: Strong Q2
A3: INFY | B3: IT | C3: Midcap IT tailwind
A4: HDFCBANK | B4: Banking | C4: Strong AUM
A5: TATAMOTORS | B5: Auto | C5: EV segment
A6: SUNPHARMA | B6: Pharma | C6: US generics
A7: ANGELONE | B7: Broking | C7: Weak guidance
A8: NMDC | B8: Metals | C8: Iron ore vol.
A9: NATCOPHARM | B9: Pharma | C9: Quick commerce
A10: PRAJIND | B10: Energy | C10: Crude recovery
A11: COCHINSHIP | B11: Defence | C11: Order book
A12: CHAMBLFERT | B12: Chemicals | C12: Sector tailwind
... A126: JAMNAAUTO | B126: Auto Ancillary | C126: CV leaf springs

Sheet Performance Dashboard
A1: 📊 PERFORMANCE DASHBOARD — Auto-populates from Trade Tracker in real time
A2: Every number, every %, every trade count — all pulled live from Trade Tracker. Just add trades there and this updates.
A5: Total Calls | B5: Wins ✅ | C5: Losses ❌ | D5: Open Trades | E5: Win Rate | F5: Avg Win % | G5: Avg Loss % | H5: Best Call % | I5: Worst Loss % | J5: T3 Hit Rate
A6: =COUNTA('Trade Tracker'!B5:B167)-COUNTIF('Trade Tracker'!B5:B167,"← Add ticker")-COUNTIF('Trade Tracker'!B5:B167,"") -> 133 | B6: =COUNTIF('Trade Tracker'!O5:O167,"WIN") -> 84 | C6: =COUNTIF('Trade Tracker'!O5:O167,"LOSS") -> 25 | D6: =COUNTIF('Trade Tracker'!O5:O167,"OPEN") -> 54 | E6: =IFERROR(COUNTIF('Trade Tracker'!O5:O167,"WIN")/(COUNTIF('Trade Tracker'!O5:O167,"WIN")+COUNTIF('Trade Tracker'!O5:O167,"LOSS")),0) -> 0.7706422 | F6: =IFERROR(AVERAGEIF('Trade Tracker'!O5:O167,"WIN",'Trade Tracker'!P5:P167),0) -> 0.24018344 | G6: =IFERROR(AVERAGEIF('Trade Tracker'!O5:O167,"LOSS",'Trade Tracker'!P5:P167),0) -> -0.04299296 | H6: =IFERROR(maxifs('Trade Tracker'!P5:P167,'Trade Tracker'!O5:O167,"WIN"),0) -> 0 | I6: =IFERROR(minifs('Trade Tracker'!P5:P167,'Trade Tracker'!O5:O167,"LOSS"),0) -> 0 | J6: =IFERROR(COUNTIF('Trade Tracker'!Q5:Q167,"T3")/COUNTIF('Trade Tracker'!O5:O167,"WIN"),0) -> 0.4047619
A9: 🏆 TOP 10 PERFORMERS (auto-pulled, sorted by return %) | H9: 🏭 SECTOR BREAKDOWN
A10: Rank | B10: Symbol | C10: Sector | D10: Entry Date | E10: Target | F10: Return % | H10: Sector | I10: Recs | J10: Win Rate
A11: 1 | B11: =IFERROR(INDEX('Trade Tracker'!B$5:B$167,MATCH(LARGE(IF('Trade Tracker'!O$5:O$167="WIN",IF(ISNUMBER('Trade Tracker'!P$5:P$167),'Trade Tracker'!P$5:P$167)),1),'Trade Tracker'!P$5:P$167,0)),"–") -> MTARTECH | C11: =IFERROR(INDEX('Trade Tracker'!S$5:S$167,MATCH(LARGE(IF('Trade Tracker'!O$5:O$167="WIN",IF(ISNUMBER('Trade Tracker'!P$5:P$167),'Trade Tracker'!P$5:P$167)),1),'Trade Tracker'!P$5:P$167,0)),"–") -> Defence | D11: =IFERROR(INDEX('Trade Tracker'!D$5:D$167,MATCH(LARGE(IF('Trade Tracker'!O$5:O$167="WIN",IF(ISNUMBER('Trade Tracker'!P$5:P$167),'Trade Tracker'!P$5:P$167)),1),'Trade Tracker'!P$5:P$167,0)),"–") -> 01 Feb 2026 | E11: =IFERROR(INDEX('Trade Tracker'!Q$5:Q$167,MATCH(LARGE(IF('Trade Tracker'!O$5:O$167="WIN",IF(ISNUMBER('Trade Tracker'!P$5:P$167),'Trade Tracker'!P$5:P$167)),1),'Trade Tracker'!P$5:P$167,0)),"–") -> T3 | F11: =IFERROR(INDEX('Trade Tracker'!P$5:P$167,MATCH(LARGE(IF('Trade Tracker'!O$5:O$167="WIN",IF(ISNUMBER('Trade Tracker'!P$5:P$167),'Trade Tracker'!P$5:P$167)),1),'Trade Tracker'!P$5:P$167,0)),"–") -> 1.653061 | H11: AMC | I11: 2 | J11: 1
A12: 2 | B12: =IFERROR(INDEX('Trade Tracker'!B$5:B$167,MATCH(LARGE(IF('Trade Tracker'!O$5:O$167="WIN",IF(ISNUMBER('Trade Tracker'!P$5:P$167),'Trade Tracker'!P$5:P$167)),2),'Trade Tracker'!P$5:P$167,0)),"–") -> – | C12: =IFERROR(INDEX('Trade Tracker'!S$5:S$167,MATCH(LARGE(IF('Trade Tracker'!O$5:O$167="WIN",IF(ISNUMBER('Trade Tracker'!P$5:P$167),'Trade Tracker'!P$5:P$167)),2),'Trade Tracker'!P$5:P$167,0)),"–") -> – | D12: =IFERROR(INDEX('Trade Tracker'!D$5:D$167,MATCH(LARGE(IF('Trade Tracker'!O$5:O$167="WIN",IF(ISNUMBER('Trade Tracker'!P$5:P$167),'Trade Tracker'!P$5:P$167)),2),'Trade Tracker'!P$5:P$167,0)),"–") -> – | E12: =IFERROR(INDEX('Trade Tracker'!Q$5:Q$167,MATCH(LARGE(IF('Trade Tracker'!O$5:O$167="WIN",IF(ISNUMBER('Trade Tracker'!P$5:P$167),'Trade Tracker'!P$5:P$167)),2),'Trade Tracker'!P$5:P$167,0)),"–") -> – | F12: =IFERROR(INDEX('Trade Tracker'!P$5:P$167,MATCH(LARGE(IF('Trade Tracker'!O$5:O$167="WIN",IF(ISNUMBER('Trade Tracker'!P$5:P$167),'Trade Tracker'!P$5:P$167)),2),'Trade Tracker'!P$5:P$167,0)),"–") -> – | H12: Agri | I12: 2 | J12: 0
A13: 3 | B13: =IFERROR(INDEX('Trade Tracker'!B$5:B$167,MATCH(LARGE(IF('Trade Tracker'!O$5:O$167="WIN",IF(ISNUMBER('Trade Tracker'!P$5:P$167),'Trade Tracker'!P$5:P$167)),3),'Trade Tracker'!P$5:P$167,0)),"–") -> JPPOWER | C13: =IFERROR(INDEX('Trade Tracker'!S$5:S$167,MATCH(LARGE(IF('Trade Tracker'!O$5:O$167="WIN",IF(ISNUMBER('Trade Tracker'!P$5:P$167),'Trade Tracker'!P$5:P$167)),3),'Trade Tracker'!P$5:P$167,0)),"–") -> Power | D13: =IFERROR(INDEX('Trade Tracker'!D$5:D$167,MATCH(LARGE(IF('Trade Tracker'!O$5:O$167="WIN",IF(ISNUMBER('Trade Tracker'!P$5:P$167),'Trade Tracker'!P$5:P$167)),3),'Trade Tracker'!P$5:P$167,0)),"–") -> 01 Apr 2026 | E13: =IFERROR(INDEX('Trade Tracker'!Q$5:Q$167,MATCH(LARGE(IF('Trade Tracker'!O$5:O$167="WIN",IF(ISNUMBER('Trade Tracker'!P$5:P$167),'Trade Tracker'!P$5:P$167)),3),'Trade Tracker'!P$5:P$167,0)),"–") -> T3 | F13: =IFERROR(INDEX('Trade Tracker'!P$5:P$167,MATCH(LARGE(IF('Trade Tracker'!O$5:O$167="WIN",IF(ISNUMBER('Trade Tracker'!P$5:P$167),'Trade Tracker'!P$5:P$167)),3),'Trade Tracker'!P$5:P$167,0)),"–") -> 1.142857 | H13: Auto | I13: 8 | J13: 0.75
A14: 4 | B14: =IFERROR(INDEX('Trade Tracker'!B$5:B$167,MATCH(LARGE(IF('Trade Tracker'!O$5:O$167="WIN",IF(ISNUMBER('Trade Tracker'!P$5:P$167),'Trade Tracker'!P$5:P$167)),4),'Trade Tracker'!P$5:P$167,0)),"–") -> STLTECH | C14: =IFERROR(INDEX('Trade Tracker'!S$5:S$167,MATCH(LARGE(IF('Trade Tracker'!O$5:O$167="WIN",IF(ISNUMBER('Trade Tracker'!P$5:P$167),'Trade Tracker'!P$5:P$167)),4),'Trade Tracker'!P$5:P$167,0)),"–") -> Telecom | D14: =IFERROR(INDEX('Trade Tracker'!D$5:D$167,MATCH(LARGE(IF('Trade Tracker'!O$5:O$167="WIN",IF(ISNUMBER('Trade Tracker'!P$5:P$167),'Trade Tracker'!P$5:P$167)),4),'Trade Tracker'!P$5:P$167,0)),"–") -> 08 Feb 2026 | E14: =IFERROR(INDEX('Trade Tracker'!Q$5:Q$167,MATCH(LARGE(IF('Trade Tracker'!O$5:O$167="WIN",IF(ISNUMBER('Trade Tracker'!P$5:P$167),'Trade Tracker'!P$5:P$167)),4),'Trade Tracker'!P$5:P$167,0)),"–") -> T3 | F14: =IFERROR(INDEX('Trade Tracker'!P$5:P$167,MATCH(LARGE(IF('Trade Tracker'!O$5:O$167="WIN",IF(ISNUMBER('Trade Tracker'!P$5:P$167),'Trade Tracker'!P$5:P$167)),4),'Trade Tracker'!P$5:P$167,0)),"–") -> 0.787879 | H14: Auto Ancillary | I14: 2 | J14: 1
A15: 5 | B15: =IFERROR(INDEX('Trade Tracker'!B$5:B$167,MATCH(LARGE(IF('Trade Tracker'!O$5:O$167="WIN",IF(ISNUMBER('Trade Tracker'!P$5:P$167),'Trade Tracker'!P$5:P$167)),5),'Trade Tracker'!P$5:P$167,0)),"–") -> – | C15: =IFERROR(INDEX('Trade Tracker'!S$5:S$167,MATCH(LARGE(IF('Trade Tracker'!O$5:O$167="WIN",IF(ISNUMBER('Trade Tracker'!P$5:P$167),'Trade Tracker'!P$5:P$167)),5),'Trade Tracker'!P$5:P$167,0)),"–") -> – | D15: =IFERROR(INDEX('Trade Tracker'!D$5:D$167,MATCH(LARGE(IF('Trade Tracker'!O$5:O$167="WIN",IF(ISNUMBER('Trade Tracker'!P$5:P$167),'Trade Tracker'!P$5:P$167)),5),'Trade Tracker'!P$5:P$167,0)),"–") -> – | E15: =IFERROR(INDEX('Trade Tracker'!Q$5:Q$167,MATCH(LARGE(IF('Trade Tracker'!O$5:O$167="WIN",IF(ISNUMBER('Trade Tracker'!P$5:P$167),'Trade Tracker'!P$5:P$167)),5),'Trade Tracker'!P$5:P$167,0)),"–") -> – | F15: =IFERROR(INDEX('Trade Tracker'!P$5:P$167,MATCH(LARGE(IF('Trade Tracker'!O$5:O$167="WIN",IF(ISNUMBER('Trade Tracker'!P$5:P$167),'Trade Tracker'!P$5:P$167)),5),'Trade Tracker'!P$5:P$167,0)),"–") -> – | H15: Banking | I15: 7 | J15: 0.57142857
A16: 6 | B16: =IFERROR(INDEX('Trade Tracker'!B$5:B$167,MATCH(LARGE(IF('Trade Tracker'!O$5:O$167="WIN",IF(ISNUMBER('Trade Tracker'!P$5:P$167),'Trade Tracker'!P$5:P$167)),6),'Trade Tracker'!P$5:P$167,0)),"–") -> BSE | C16: =IFERROR(INDEX('Trade Tracker'!S$5:S$167,MATCH(LARGE(IF('Trade Tracker'!O$5:O$167="WIN",IF(ISNUMBER('Trade Tracker'!P$5:P$167),'Trade Tracker'!P$5:P$167)),6),'Trade Tracker'!P$5:P$167,0)),"–") -> Finance | D16: =IFERROR(INDEX('Trade Tracker'!D$5:D$167,MATCH(LARGE(IF('Trade Tracker'!O$5:O$167="WIN",IF(ISNUMBER('Trade Tracker'!P$5:P$167),'Trade Tracker'!P$5:P$167)),6),'Trade Tracker'!P$5:P$167,0)),"–") -> 03 Nov 2025 | E16: =IFERROR(INDEX('Trade Tracker'!Q$5:Q$167,MATCH(LARGE(IF('Trade Tracker'!O$5:O$167="WIN",IF(ISNUMBER('Trade Tracker'!P$5:P$167),'Trade Tracker'!P$5:P$167)),6),'Trade Tracker'!P$5:P$167,0)),"–") -> T3 | F16: =IFERROR(INDEX('Trade Tracker'!P$5:P$167,MATCH(LARGE(IF('Trade Tracker'!O$5:O$167="WIN",IF(ISNUMBER('Trade Tracker'!P$5:P$167),'Trade Tracker'!P$5:P$167)),6),'Trade Tracker'!P$5:P$167,0)),"–") -> 0.562 | H16: Broking | I16: 1 | J16: 1
A17: 7 | B17: =IFERROR(INDEX('Trade Tracker'!B$5:B$167,MATCH(LARGE(IF('Trade Tracker'!O$5:O$167="WIN",IF(ISNUMBER('Trade Tracker'!P$5:P$167),'Trade Tracker'!P$5:P$167)),7),'Trade Tracker'!P$5:P$167,0)),"–") -> PRECWIRE | C17: =IFERROR(INDEX('Trade Tracker'!S$5:S$167,MATCH(LARGE(IF('Trade Tracker'!O$5:O$167="WIN",IF(ISNUMBER('Trade Tracker'!P$5:P$167),'Trade Tracker'!P$5:P$167)),7),'Trade Tracker'!P$5:P$167,0)),"–") -> Industrials | D17: =IFERROR(INDEX('Trade Tracker'!D$5:D$167,MATCH(LARGE(IF('Trade Tracker'!O$5:O$167="WIN",IF(ISNUMBER('Trade Tracker'!P$5:P$167),'Trade Tracker'!P$5:P$167)),7),'Trade Tracker'!P$5:P$167,0)),"–") -> 27 Jan 2026 | E17: =IFERROR(INDEX('Trade Tracker'!Q$5:Q$167,MATCH(LARGE(IF('Trade Tracker'!O$5:O$167="WIN",IF(ISNUMBER('Trade Tracker'!P$5:P$167),'Trade Tracker'!P$5:P$167)),7),'Trade Tracker'!P$5:P$167,0)),"–") -> T3 | F17: =IFERROR(INDEX('Trade Tracker'!P$5:P$167,MATCH(LARGE(IF('Trade Tracker'!O$5:O$167="WIN",IF(ISNUMBER('Trade Tracker'!P$5:P$167),'Trade Tracker'!P$5:P$167)),7),'Trade Tracker'!P$5:P$167,0)),"–") -> 0.491228 | H17: Cement | I17: 1 | J17: 0
A18: 8 | B18: =IFERROR(INDEX('Trade Tracker'!B$5:B$167,MATCH(LARGE(IF('Trade Tracker'!O$5:O$167="WIN",IF(ISNUMBER('Trade Tracker'!P$5:P$167),'Trade Tracker'!P$5:P$167)),8),'Trade Tracker'!P$5:P$167,0)),"–") -> – | C18: =IFERROR(INDEX('Trade Tracker'!S$5:S$167,MATCH(LARGE(IF('Trade Tracker'!O$5:O$167="WIN",IF(ISNUMBER('Trade Tracker'!P$5:P$167),'Trade Tracker'!P$5:P$167)),8),'Trade Tracker'!P$5:P$167,0)),"–") -> – | D18: =IFERROR(INDEX('Trade Tracker'!D$5:D$167,MATCH(LARGE(IF('Trade Tracker'!O$5:O$167="WIN",IF(ISNUMBER('Trade Tracker'!P$5:P$167),'Trade Tracker'!P$5:P$167)),8),'Trade Tracker'!P$5:P$167,0)),"–") -> – | E18: =IFERROR(INDEX('Trade Tracker'!Q$5:Q$167,MATCH(LARGE(IF('Trade Tracker'!O$5:O$167="WIN",IF(ISNUMBER('Trade Tracker'!P$5:P$167),'Trade Tracker'!P$5:P$167)),8),'Trade Tracker'!P$5:P$167,0)),"–") -> – | F18: =IFERROR(INDEX('Trade Tracker'!P$5:P$167,MATCH(LARGE(IF('Trade Tracker'!O$5:O$167="WIN",IF(ISNUMBER('Trade Tracker'!P$5:P$167),'Trade Tracker'!P$5:P$167)),8),'Trade Tracker'!P$5:P$167,0)),"–") -> – | H18: Chemicals | I18: 3 | J18: 0.33333333
A19: 9 | B19: =IFERROR(INDEX('Trade Tracker'!B$5:B$167,MATCH(LARGE(IF('Trade Tracker'!O$5:O$167="WIN",IF(ISNUMBER('Trade Tracker'!P$5:P$167),'Trade Tracker'!P$5:P$167)),9),'Trade Tracker'!P$5:P$167,0)),"–") -> – | C19: =IFERROR(INDEX('Trade Tracker'!S$5:S$167,MATCH(LARGE(IF('Trade Tracker'!O$5:O$167="WIN",IF(ISNUMBER('Trade Tracker'!P$5:P$167),'Trade Tracker'!P$5:P$167)),9),'Trade Tracker'!P$5:P$167,0)),"–") -> – | D19: =IFERROR(INDEX('Trade Tracker'!D$5:D$167,MATCH(LARGE(IF('Trade Tracker'!O$5:O$167="WIN",IF(ISNUMBER('Trade Tracker'!P$5:P$167),'Trade Tracker'!P$5:P$167)),9),'Trade Tracker'!P$5:P$167,0)),"–") -> – | E19: =IFERROR(INDEX('Trade Tracker'!Q$5:Q$167,MATCH(LARGE(IF('Trade Tracker'!O$5:O$167="WIN",IF(ISNUMBER('Trade Tracker'!P$5:P$167),'Trade Tracker'!P$5:P$167)),9),'Trade Tracker'!P$5:P$167,0)),"–") -> – | F19: =IFERROR(INDEX('Trade Tracker'!P$5:P$167,MATCH(LARGE(IF('Trade Tracker'!O$5:O$167="WIN",IF(ISNUMBER('Trade Tracker'!P$5:P$167),'Trade Tracker'!P$5:P$167)),9),'Trade Tracker'!P$5:P$167,0)),"–") -> – | H19: Consumer | I19: 6 | J19: 1
A20: 10 | B20: =IFERROR(INDEX('Trade Tracker'!B$5:B$167,MATCH(LARGE(IF('Trade Tracker'!O$5:O$167="WIN",IF(ISNUMBER('Trade Tracker'!P$5:P$167),'Trade Tracker'!P$5:P$167)),10),'Trade Tracker'!P$5:P$167,0)),"–") -> – | C20: =IFERROR(INDEX('Trade Tracker'!S$5:S$167,MATCH(LARGE(IF('Trade Tracker'!O$5:O$167="WIN",IF(ISNUMBER('Trade Tracker'!P$5:P$167),'Trade Tracker'!P$5:P$167)),10),'Trade Tracker'!P$5:P$167,0)),"–") -> – | D20: =IFERROR(INDEX('Trade Tracker'!D$5:D$167,MATCH(LARGE(IF('Trade Tracker'!O$5:O$167="WIN",IF(ISNUMBER('Trade Tracker'!P$5:P$167),'Trade Tracker'!P$5:P$167)),10),'Trade Tracker'!P$5:P$167,0)),"–") -> – | E20: =IFERROR(INDEX('Trade Tracker'!Q$5:Q$167,MATCH(LARGE(IF('Trade Tracker'!O$5:O$167="WIN",IF(ISNUMBER('Trade Tracker'!P$5:P$167),'Trade Tracker'!P$5:P$167)),10),'Trade Tracker'!P$5:P$167,0)),"–") -> – | F20: =IFERROR(INDEX('Trade Tracker'!P$5:P$167,MATCH(LARGE(IF('Trade Tracker'!O$5:O$167="WIN",IF(ISNUMBER('Trade Tracker'!P$5:P$167),'Trade Tracker'!P$5:P$167)),10),'Trade Tracker'!P$5:P$167,0)),"–") -> – | H20: Defence | I20: 5 | J20: 1
H21: Education | I21: 1 | J21: 1
A22: 🔻 WORST 5 LOSSES (SL exits only) | H22: Energy | I22: 6 | J22: 0.5
A23: Rank | B23: Symbol | C23: Sector | D23: Entry Date | E23: Exit | F23: Loss % | H23: FMCG | I23: 2 | J23: 0.5
A24: 1 | B24: =IFERROR(INDEX('Trade Tracker'!B$5:B$167,MATCH(SMALL(IF('Trade Tracker'!O$5:O$167="LOSS",IF(ISNUMBER('Trade Tracker'!P$5:P$167),'Trade Tracker'!P$5:P$167)),1),'Trade Tracker'!P$5:P$167,0)),"–") -> POLYMED | C24: =IFERROR(INDEX('Trade Tracker'!S$5:S$167,MATCH(SMALL(IF('Trade Tracker'!O$5:O$167="LOSS",IF(ISNUMBER('Trade Tracker'!P$5:P$167),'Trade Tracker'!P$5:P$167)),1),'Trade Tracker'!P$5:P$167,0)),"–") -> Healthcare | D24: =IFERROR(INDEX('Trade Tracker'!D$5:D$167,MATCH(SMALL(IF('Trade Tracker'!O$5:O$167="LOSS",IF(ISNUMBER('Trade Tracker'!P$5:P$167),'Trade Tracker'!P$5:P$167)),1),'Trade Tracker'!P$5:P$167,0)),"–") -> 24 Nov 2025 | E24: =IFERROR(INDEX('Trade Tracker'!Q$5:Q$167,MATCH(SMALL(IF('Trade Tracker'!O$5:O$167="LOSS",IF(ISNUMBER('Trade Tracker'!P$5:P$167),'Trade Tracker'!P$5:P$167)),1),'Trade Tracker'!P$5:P$167,0)),"–") -> T4 | F24: =IFERROR(INDEX('Trade Tracker'!P$5:P$167,MATCH(SMALL(IF('Trade Tracker'!O$5:O$167="LOSS",IF(ISNUMBER('Trade Tracker'!P$5:P$167),'Trade Tracker'!P$5:P$167)),1),'Trade Tracker'!P$5:P$167,0)),"–") -> 0 | H24: Finance | I24: 9 | J24: 0.55555556
A25: 2 | B25: =IFERROR(INDEX('Trade Tracker'!B$5:B$167,MATCH(SMALL(IF('Trade Tracker'!O$5:O$167="LOSS",IF(ISNUMBER('Trade Tracker'!P$5:P$167),'Trade Tracker'!P$5:P$167)),2),'Trade Tracker'!P$5:P$167,0)),"–") -> – | C25: =IFERROR(INDEX('Trade Tracker'!S$5:S$167,MATCH(SMALL(IF('Trade Tracker'!O$5:O$167="LOSS",IF(ISNUMBER('Trade Tracker'!P$5:P$167),'Trade Tracker'!P$5:P$167)),2),'Trade Tracker'!P$5:P$167,0)),"–") -> – | D25: =IFERROR(INDEX('Trade Tracker'!D$5:D$167,MATCH(SMALL(IF('Trade Tracker'!O$5:O$167="LOSS",IF(ISNUMBER('Trade Tracker'!P$5:P$167),'Trade Tracker'!P$5:P$167)),2),'Trade Tracker'!P$5:P$167,0)),"–") -> – | E25: =IFERROR(INDEX('Trade Tracker'!Q$5:Q$167,MATCH(SMALL(IF('Trade Tracker'!O$5:O$167="LOSS",IF(ISNUMBER('Trade Tracker'!P$5:P$167),'Trade Tracker'!P$5:P$167)),2),'Trade Tracker'!P$5:P$167,0)),"–") -> – | F25: =IFERROR(INDEX('Trade Tracker'!P$5:P$167,MATCH(SMALL(IF('Trade Tracker'!O$5:O$167="LOSS",IF(ISNUMBER('Trade Tracker'!P$5:P$167),'Trade Tracker'!P$5:P$167)),2),'Trade Tracker'!P$5:P$167,0)),"–") -> – | H25: Healthcare | I25: 3 | J25: 0.66666667
A26: 3 | B26: =IFERROR(INDEX('Trade Tracker'!B$5:B$167,MATCH(SMALL(IF('Trade Tracker'!O$5:O$167="LOSS",IF(ISNUMBER('Trade Tracker'!P$5:P$167),'Trade Tracker'!P$5:P$167)),3),'Trade Tracker'!P$5:P$167,0)),"–") -> – | C26: =IFERROR(INDEX('Trade Tracker'!S$5:S$167,MATCH(SMALL(IF('Trade Tracker'!O$5:O$167="LOSS",IF(ISNUMBER('Trade Tracker'!P$5:P$167),'Trade Tracker'!P$5:P$167)),3),'Trade Tracker'!P$5:P$167,0)),"–") -> – | D26: =IFERROR(INDEX('Trade Tracker'!D$5:D$167,MATCH(SMALL(IF('Trade Tracker'!O$5:O$167="LOSS",IF(ISNUMBER('Trade Tracker'!P$5:P$167),'Trade Tracker'!P$5:P$167)),3),'Trade Tracker'!P$5:P$167,0)),"–") -> – | E26: =IFERROR(INDEX('Trade Tracker'!Q$5:Q$167,MATCH(SMALL(IF('Trade Tracker'!O$5:O$167="LOSS",IF(ISNUMBER('Trade Tracker'!P$5:P$167),'Trade Tracker'!P$5:P$167)),3),'Trade Tracker'!P$5:P$167,0)),"–") -> – | F26: =IFERROR(INDEX('Trade Tracker'!P$5:P$167,MATCH(SMALL(IF('Trade Tracker'!O$5:O$167="LOSS",IF(ISNUMBER('Trade Tracker'!P$5:P$167),'Trade Tracker'!P$5:P$167)),3),'Trade Tracker'!P$5:P$167,0)),"–") -> – | H26: Hospitality | I26: 1 | J26: 0
A27: 4 | B27: =IFERROR(INDEX('Trade Tracker'!B$5:B$167,MATCH(SMALL(IF('Trade Tracker'!O$5:O$167="LOSS",IF(ISNUMBER('Trade Tracker'!P$5:P$167),'Trade Tracker'!P$5:P$167)),4),'Trade Tracker'!P$5:P$167,0)),"–") -> – | C27: =IFERROR(INDEX('Trade Tracker'!S$5:S$167,MATCH(SMALL(IF('Trade Tracker'!O$5:O$167="LOSS",IF(ISNUMBER('Trade Tracker'!P$5:P$167),'Trade Tracker'!P$5:P$167)),4),'Trade Tracker'!P$5:P$167,0)),"–") -> – | D27: =IFERROR(INDEX('Trade Tracker'!D$5:D$167,MATCH(SMALL(IF('Trade Tracker'!O$5:O$167="LOSS",IF(ISNUMBER('Trade Tracker'!P$5:P$167),'Trade Tracker'!P$5:P$167)),4),'Trade Tracker'!P$5:P$167,0)),"–") -> – | E27: =IFERROR(INDEX('Trade Tracker'!Q$5:Q$167,MATCH(SMALL(IF('Trade Tracker'!O$5:O$167="LOSS",IF(ISNUMBER('Trade Tracker'!P$5:P$167),'Trade Tracker'!P$5:P$167)),4),'Trade Tracker'!P$5:P$167,0)),"–") -> – | F27: =IFERROR(INDEX('Trade Tracker'!P$5:P$167,MATCH(SMALL(IF('Trade Tracker'!O$5:O$167="LOSS",IF(ISNUMBER('Trade Tracker'!P$5:P$167),'Trade Tracker'!P$5:P$167)),4),'Trade Tracker'!P$5:P$167,0)),"–") -> – | H27: IT | I27: 7 | J27: 0.71428571
A28: 5 | B28: =IFERROR(INDEX('Trade Tracker'!B$5:B$167,MATCH(SMALL(IF('Trade Tracker'!O$5:O$167="LOSS",IF(ISNUMBER('Trade Tracker'!P$5:P$167),'Trade Tracker'!P$5:P$167)),5),'Trade Tracker'!P$5:P$167,0)),"–") -> – | C28: =IFERROR(INDEX('Trade Tracker'!S$5:S$167,MATCH(SMALL(IF('Trade Tracker'!O$5:O$167="LOSS",IF(ISNUMBER('Trade Tracker'!P$5:P$167),'Trade Tracker'!P$5:P$167)),5),'Trade Tracker'!P$5:P$167,0)),"–") -> – | D28: =IFERROR(INDEX('Trade Tracker'!D$5:D$167,MATCH(SMALL(IF('Trade Tracker'!O$5:O$167="LOSS",IF(ISNUMBER('Trade Tracker'!P$5:P$167),'Trade Tracker'!P$5:P$167)),5),'Trade Tracker'!P$5:P$167,0)),"–") -> – | E28: =IFERROR(INDEX('Trade Tracker'!Q$5:Q$167,MATCH(SMALL(IF('Trade Tracker'!O$5:O$167="LOSS",IF(ISNUMBER('Trade Tracker'!P$5:P$167),'Trade Tracker'!P$5:P$167)),5),'Trade Tracker'!P$5:P$167,0)),"–") -> – | F28: =IFERROR(INDEX('Trade Tracker'!P$5:P$167,MATCH(SMALL(IF('Trade Tracker'!O$5:O$167="LOSS",IF(ISNUMBER('Trade Tracker'!P$5:P$167),'Trade Tracker'!P$5:P$167)),5),'Trade Tracker'!P$5:P$167,0)),"–") -> – | H28: Industrials | I28: 8 | J28: 1
H29: Infrastructure | I29: 1 | J29: 1
H30: Logistics | I30: 2 | J30: 1
H31: Media | I31: 1 | J31: 1
H32: Metals | I32: 13 | J32: 0.92307692
H33: NBFC | I33: 8 | J33: 0.875
H34: Packaging | I34: 0 | J34: 0
H35: Pharma | I35: 3 | J35: 1
H36: Power | I36: 2 | J36: 1
H37: Real Estate | I37: 1 | J37: 0
H38: Realty | I38: 1 | J38: 1
H39: Retail | I39: 2 | J39: 1
H40: Telecom | I40: 1 | J40: 1

Sheet Trade Tracker
A1: 📈 JAIN CAPITAL — TRADE TRACKER | Live CMP via GOOGLEFINANCE | All sheets auto-populate from this tab
A2: YELLOW = CMP auto-fetched | WIN/LOSS locked permanently | Sector & Notes auto-fill via VLOOKUP | All dashboards update instantly
A4: # | B4: Symbol | C4: Company | D4: Rec Date | E4: Buy Low | F4: Buy High | G4: Exch | H4: Live CMP | I4: T1 ₹ | J4: T2 ₹ | K4: T3 ₹ | L4: Stop Loss | M4: Live Status | N4: Alert | O4: Result | P4: % Return | Q4: Best Target | R4: Days Held | S4: Sector (Auto) | T4: Notes (Auto) | U4: Exit Date | V4: Exit Price
A5: 1 | B5: HDFCBANK | C5: HDFC Bank | D5: 16 Sep 2024 | E5: 800 | F5: 820 | G5: NSE: | H5: =IFERROR(googlefinance("NSE:HDFCBANK","price"),"–") -> – | I5: 850 | J5: 890 | K5: 940 | L5: 780 | M5: 🔴 SL EXIT | N5: ⚠️ SL Exit -2.5% | O5: LOSS | P5: -0.025 | Q5: SL | R5: 15 | S5: =IFERROR(VLOOKUP(B5,SectorMap!A:B,2,0),"Banking") -> Banking | T5: =IFERROR(VLOOKUP(B5,SectorMap!A:C,3,0),"RBI policy") -> Strong AUM | U5: 01 Oct 2024 | V5: 780
A6: 2 | B6: INFY | C6: Infosys | D6: 05 Oct 2024 | E6: 1750 | F6: 1780 | G6: NSE: | H6: =IFERROR(googlefinance("NSE:INFY","price"),"–") -> – | I6: 1830 | J6: 1900 | K6: 2000 | L6: 1700 | M6: 🔴 SL EXIT | N6: ⚠️ SL Exit -2.9% | O6: LOSS | P6: -0.028571 | Q6: SL | R6: 15 | S6: =IFERROR(VLOOKUP(B6,SectorMap!A:B,2,0),"IT") -> IT | T6: =IFERROR(VLOOKUP(B6,SectorMap!A:C,3,0),"Midcap IT tailwind") -> Midcap IT tailwind | U6: 20 Oct 2024 | V6: 1700
A7: 3 | B7: TATAMOTORS | C7: Tata Motors | D7: 19 Oct 2024 | E7: 390 | F7: 400 | G7: NSE: | H7: =IFERROR(googlefinance("NSE:TATAMOTORS","price"),"–") -> – | I7: 420 | J7: 450 | K7: 490 | L7: 375 | M7: 🔴 SL EXIT | N7: ⚠️ SL Exit -3.8% | O7: LOSS | P7: -0.038462 | Q7: SL | R7: 15 | S7: =IFERROR(VLOOKUP(B7,SectorMap!A:B,2,0),"Auto") -> Auto | T7: =IFERROR(VLOOKUP(B7,SectorMap!A:C,3,0),"EV segment") -> EV segment | U7: 03 Nov 2024 | V7: 375
A8: 4 | B8: SUNPHARMA | C8: Sun Pharma | D8: 30 Oct 2024 | E8: 1680 | F8: 1720 | G8: NSE: | H8: =IFERROR(googlefinance("NSE:SUNPHARMA","price"),"–") -> – | I8: 1780 | J8: 1850 | K8: 1950 | L8: 1640 | M8: 🏆 BOOKED — T1 | N8: ✅ Booked T1 +6.0% | O8: WIN | P8: 0.059524 | Q8: T1 | R8: 30 | S8: =IFERROR(VLOOKUP(B8,SectorMap!A:B,2,0),"Pharma") -> Pharma | T8: =IFERROR(VLOOKUP(B8,SectorMap!A:C,3,0),"US generics") -> US generics | U8: 29 Nov 2024 | V8: 1780
A9: 5 | B9: PNBHOUSING | C9: PNB HOUSING | D9: 23 Oct 2025 | E9: 900 | F9: 905 | G9: NSE: | H9: =IFERROR(googlefinance("NSE:PNBHOUSING","price"),"–") -> – | I9: 950 | J9: 1000 | K9: 1089 | L9: 800 | M9: 🏆 BOOKED — T3 | N9: ✅ Booked T3 +21.0% | O9: WIN | P9: 0.21 | Q9: T3 | R9: 60 | S9: =IFERROR(VLOOKUP(B9,SectorMap!A:B,2,0),"NBFC") -> NBFC | T9: =IFERROR(VLOOKUP(B9,SectorMap!A:C,3,0),"Housing demand") -> Housing demand | U9: 22 Dec 2025 | V9: 1089
A10: 6 | B10: CREDITACC | C10: CREDIT ACCESS | D10: 24 Oct 2025 | E10: 1400 | F10: 1425 | G10: NSE: | H10: =IFERROR(googlefinance("NSE:CREDITACC","price"),"–") -> – | I10: 1497 | J10: 1550 | K10: 1600 | L10: 1250 | M10: 🏆 BOOKED — T1 | N10: ✅ Booked T1 +6.9% | O10: WIN | P10: 0.069286 | Q10: T1 | R10: 30 | S10: =IFERROR(VLOOKUP(B10,SectorMap!A:B,2,0),"NBFC") -> NBFC | T10: =IFERROR(VLOOKUP(B10,SectorMap!A:C,3,0),"Microfinance") -> Microfinance | U10: 23 Nov 2025 | V10: 1497
A11: 7 | B11: HINDALCO | C11: HINDALCO | D11: 24 Oct 2025 | E11: 800 | F11: 825 | G11: NSE: | H11: =IFERROR(googlefinance("NSE:HINDALCO","price"),"–") -> – | I11: 925 | J11: 1000 | K11: 1044 | L11: 750 | M11: 🏆 BOOKED — T3 | N11: ✅ Booked T3 +30.5% | O11: WIN | P11: 0.305 | Q11: T3 | R11: 60 | S11: =IFERROR(VLOOKUP(B11,SectorMap!A:B,2,0),"Metals") -> Metals | T11: =IFERROR(VLOOKUP(B11,SectorMap!A:C,3,0),"Aluminium upcycle") -> Aluminium upcycle | U11: 23 Dec 2025 | V11: 1044
A12: 8 | B12: NBCC | C12: NBCC | D12: 24 Oct 2025 | E12: 100 | F12: 105 | G12: NSE: | H12: =IFERROR(googlefinance("NSE:NBCC","price"),"–") -> – | I12: 120 | J12: 125 | K12: – | L12: 95 | M12: =IF(OR(H12="",H12="–"),"–",IFERROR(IF(H12<L12,"🔴 SL Hit",IF(AND(ISNUMBER(K12),H12>=K12),"🎯 T3 Hit — Book!",IF(AND(ISNUMBER(J12),H12>=J12),"🎯 T2 Hit — Book!",IF(AND(ISNUMBER(I12),H12>=I12),"🎯 T1 Hit — Book!",IF(AND(H12>=E12),"🟡 In/Above Buy Zone","🔻 Below Buy Zone"))))),"-")) -> – | N12: =IF(M12="🎯 T3 Hit — Book!","🏆 BOOK T3 PROFITS!",IF(M12="🎯 T2 Hit — Book!","🎯 BOOK T2 PROFITS!",IF(M12="🎯 T1 Hit — Book!","📈 BOOK T1 PROFITS!",IF(M12="🔴 SL Hit","⚠️ EXIT NOW!",IF(M12="🟡 In/Above Buy Zone","🔔 BUY NOW!","⏳ Wait"))))) -> ⏳ Wait | O12: OPEN | P12: =IF(OR(ISBLANK(H12),H12="–",NOT(ISNUMBER(H12)),E12=0),"–",(H12-E12)/E12) -> – | Q12: OPEN | R12: 216 | S12: =IFERROR(VLOOKUP(B12,SectorMap!A:B,2,0),"Real Estate") -> Real Estate | T12: =IFERROR(VLOOKUP(B12,SectorMap!A:C,3,0),"Govt construction") -> Govt construction | U12: Open | V12: –
A13: 9 | B13: SHANTIGOLD | C13: SHANTI GOLD | D13: 24 Oct 2025 | E13: 200 | F13: 215 | G13: NSE: | H13: =IFERROR(googlefinance("NSE:SHANTIGOLD","price"),"–") -> – | I13: 225 | J13: 250 | K13: 275 | L13: 175 | M13: 🏆 BOOKED — T1 | N13: ✅ Booked T1 +12.5% | O13: WIN | P13: 0.125 | Q13: T1 | R13: 30 | S13: =IFERROR(VLOOKUP(B13,SectorMap!A:B,2,0),"Metals") -> Metals | T13: =IFERROR(VLOOKUP(B13,SectorMap!A:C,3,0),"Gold jewellery") -> Gold jewellery | U13: 23 Nov 2025 | V13: 225
A14: 10 | B14: UJJIVANSFB | C14: UJJIVAN SFB | D14: 27 Oct 2025 | E14: 50 | F14: 52 | G14: NSE: | H14: =IFERROR(googlefinance("NSE:UJJIVANSFB","price"),"–") -> – | I14: 55 | J14: 60 | K14: 62.4 | L14: 45 | M14: 🏆 BOOKED — T3 | N14: ✅ Booked T3 +24.8% | O14: WIN | P14: 0.248 | Q14: T3 | R14: 60 | S14: =IFERROR(VLOOKUP(B14,SectorMap!A:B,2,0),"Banking") -> Banking | T14: =IFERROR(VLOOKUP(B14,SectorMap!A:C,3,0),"SFB growth") -> SFB growth | U14: 26 Dec 2025 | V14: 62.4
A15: 11 | B15: JMFINANCIL | C15: JMF | D15: 27 Oct 2025 | E15: 170 | F15: 172 | G15: NSE: | H15: =IFERROR(googlefinance("NSE:JMFINANCIL","price"),"–") -> – | I15: 178 | J15: 182 | K15: 190 | L15: 168 | M15: 🔴 SL EXIT | N15: ⚠️ SL Exit -1.2% | O15: LOSS | P15: -0.011765 | Q15: SL | R15: 15 | S15: =IFERROR(VLOOKUP(B15,SectorMap!A:B,2,0),"Finance") -> Finance | T15: =IFERROR(VLOOKUP(B15,SectorMap!A:C,3,0),"IB & lending") -> IB & lending | U15: 11 Nov 2025 | V15: 168
A16: 12 | B16: BHARATWIRE | C16: BHARAT WIRE ROPES | D16: 28 Oct 2025 | E16: 200 | F16: 206 | G16: NSE: | H16: =IFERROR(googlefinance("NSE:BHARATWIRE","price"),"–") -> – | I16: 225 | J16: 250 | K16: 260 | L16: 175 | M16: 🏆 BOOKED — T2 | N16: ✅ Booked T2 +25.0% | O16: WIN | P16: 0.25 | Q16: T2 | R16: 45 | S16: =IFERROR(VLOOKUP(B16,SectorMap!A:B,2,0),"Metals") -> Metals | T16: =IFERROR(VLOOKUP(B16,SectorMap!A:C,3,0),"Wire demand") -> Wire demand | U16: 12 Dec 2025 | V16: 250
A17: 13 | B17: AEROFLEX | C17: AEROFLEX | D17: 28 Oct 2025 | E17: 178 | F17: 182 | G17: NSE: | H17: =IFERROR(googlefinance("NSE:AEROFLEX","price"),"–") -> – | I17: 200 | J17: 300 | K17: 421 | L17: 150 | M17: 🏆 BOOKED — T3 | N17: ✅ Booked T3 +136.5% | O17: WIN | P17: 1.365169 | Q17: T3 | R17: 60 | S17: =IFERROR(VLOOKUP(B17,SectorMap!A:B,2,0),"Industrials") -> Industrials | T17: =IFERROR(VLOOKUP(B17,SectorMap!A:C,3,0),"Flexible hose") -> Flexible hose | U17: 27 Dec 2025 | V17: 421
A18: 14 | B18: JAICORPLTD | C18: JAICORP | D18: 29 Oct 2025 | E18: 170 | F18: 172 | G18: NSE: | H18: =IFERROR(googlefinance("NSE:JAICORPLTD","price"),"–") -> – | I18: 180 | J18: 190 | K18: – | L18: 160 | M18: 🔴 SL EXIT | N18: ⚠️ SL Exit -5.9% | O18: LOSS | P18: -0.058824 | Q18: SL | R18: 15 | S18: =IFERROR(VLOOKUP(B18,SectorMap!A:B,2,0),"Real Estate") -> Real Estate | T18: =IFERROR(VLOOKUP(B18,SectorMap!A:C,3,0),"Land monetisation") -> Land monetisation | U18: 13 Nov 2025 | V18: 160
A19: 15 | B19: SAGILITY | C19: SAGILITY | D19: 29 Oct 2025 | E19: 45 | F19: 46 | G19: NSE: | H19: =IFERROR(googlefinance("NSE:SAGILITY","price"),"–") -> – | I19: 50 | J19: 55 | K19: 60 | L19: 40 | M19: =IF(OR(H19="",H19="–"),"–",IFERROR(IF(H19<L19,"🔴 SL Hit",IF(AND(ISNUMBER(K19),H19>=K19),"🎯 T3 Hit — Book!",IF(AND(ISNUMBER(J19),H19>=J19),"🎯 T2 Hit — Book!",IF(AND(ISNUMBER(I19),H19>=I19),"🎯 T1 Hit — Book!",IF(AND(H19>=E19),"🟡 In/Above Buy Zone","🔻 Below Buy Zone"))))),"-")) -> – | N19: =IF(M19="🎯 T3 Hit — Book!","🏆 BOOK T3 PROFITS!",IF(M19="🎯 T2 Hit — Book!","🎯 BOOK T2 PROFITS!",IF(M19="🎯 T1 Hit — Book!","📈 BOOK T1 PROFITS!",IF(M19="🔴 SL Hit","⚠️ EXIT NOW!",IF(M19="🟡 In/Above Buy Zone","🔔 BUY NOW!","⏳ Wait"))))) -> ⏳ Wait | O19: OPEN | P19: =IF(OR(ISBLANK(H19),H19="–",NOT(ISNUMBER(H19)),E19=0),"–",(H19-E19)/E19) -> – | Q19: OPEN | R19: 211 | S19: =IFERROR(VLOOKUP(B19,SectorMap!A:B,2,0),"IT") -> IT | T19: =IFERROR(VLOOKUP(B19,SectorMap!A:C,3,0),"Healthcare BPO") -> Healthcare BPO | U19: Open | V19: –
A20: 16 | B20: CANFINHOME | C20: CAN FIN HOMES | D20: 29 Oct 2025 | E20: 850 | F20: 860 | G20: NSE: | H20: =IFERROR(googlefinance("NSE:CANFINHOME","price"),"–") -> – | I20: 890 | J20: 1000 | K20: – | L20: 800 | M20: =IF(OR(H20="",H20="–"),"–",IFERROR(IF(H20<L20,"🔴 SL Hit",IF(AND(ISNUMBER(K20),H20>=K20),"🎯 T3 Hit — Book!",IF(AND(ISNUMBER(J20),H20>=J20),"🎯 T2 Hit — Book!",IF(AND(ISNUMBER(I20),H20>=I20),"🎯 T1 Hit — Book!",IF(AND(H20>=E20),"🟡 In/Above Buy Zone","🔻 Below Buy Zone"))))),"-")) -> – | N20: =IF(M20="🎯 T3 Hit — Book!","🏆 BOOK T3 PROFITS!",IF(M20="🎯 T2 Hit — Book!","🎯 BOOK T2 PROFITS!",IF(M20="🎯 T1 Hit — Book!","📈 BOOK T1 PROFITS!",IF(M20="🔴 SL Hit","⚠️ EXIT NOW!",IF(M20="🟡 In/Above Buy Zone","🔔 BUY NOW!","⏳ Wait"))))) -> ⏳ Wait | O20: OPEN | P20: =IF(OR(ISBLANK(H20),H20="–",NOT(ISNUMBER(H20)),E20=0),"–",(H20-E20)/E20) -> – | Q20: OPEN | R20: 211 | S20: =IFERROR(VLOOKUP(B20,SectorMap!A:B,2,0),"NBFC") -> NBFC | T20: =IFERROR(VLOOKUP(B20,SectorMap!A:C,3,0),"Affordable housing") -> Affordable housing | U20: Open | V20: –
A21: 17 | B21: ELGIEQUIP | C21: ELGI EQUIPMENT | D21: 29 Oct 2025 | E21: 490 | F21: 500 | G21: NSE: | H21: =IFERROR(googlefinance("NSE:ELGIEQUIP","price"),"–") -> – | I21: 525 | J21: 560.7 | K21: 600 | L21: 450 | M21: 🏆 BOOKED — T2 | N21: ✅ Booked T2 +14.4% | O21: WIN | P21: 0.144286 | Q21: T2 | R21: 45 | S21: =IFERROR(VLOOKUP(B21,SectorMap!A:B,2,0),"Industrials") -> Industrials | T21: =IFERROR(VLOOKUP(B21,SectorMap!A:C,3,0),"Compressor demand") -> Compressor demand | U21: 13 Dec 2025 | V21: 560.7
A22: 18 | B22: DLINKINDIA | C22: DLINK | D22: 30 Oct 2025 | E22: 460 | F22: 465 | G22: NSE: | H22: =IFERROR(googlefinance("NSE:DLINKINDIA","price"),"–") -> – | I22: 525 | J22: 550 | K22: 600 | L22: 425 | M22: =IF(OR(H22="",H22="–"),"–",IFERROR(IF(H22<L22,"🔴 SL Hit",IF(AND(ISNUMBER(K22),H22>=K22),"🎯 T3 Hit — Book!",IF(AND(ISNUMBER(J22),H22>=J22),"🎯 T2 Hit — Book!",IF(AND(ISNUMBER(I22),H22>=I22),"🎯 T1 Hit — Book!",IF(AND(H22>=E22),"🟡 In/Above Buy Zone","🔻 Below Buy Zone"))))),"-")) -> – | N22: =IF(M22="🎯 T3 Hit — Book!","🏆 BOOK T3 PROFITS!",IF(M22="🎯 T2 Hit — Book!","🎯 BOOK T2 PROFITS!",IF(M22="🎯 T1 Hit — Book!","📈 BOOK T1 PROFITS!",IF(M22="🔴 SL Hit","⚠️ EXIT NOW!",IF(M22="🟡 In/Above Buy Zone","🔔 BUY NOW!","⏳ Wait"))))) -> ⏳ Wait | O22: OPEN | P22: =IF(OR(ISBLANK(H22),H22="–",NOT(ISNUMBER(H22)),E22=0),"–",(H22-E22)/E22) -> – | Q22: OPEN | R22: 210 | S22: =IFERROR(VLOOKUP(B22,SectorMap!A:B,2,0),"Telecom") -> Telecom | T22: =IFERROR(VLOOKUP(B22,SectorMap!A:C,3,0),"Network infra") -> Network infra | U22: Open | V22: –
A23: 19 | B23: NOCIL | C23: NOCIL | D23: 30 Oct 2025 | E23: 170 | F23: 175 | G23: NSE: | H23: =IFERROR(googlefinance("NSE:NOCIL","price"),"–") -> – | I23: 180 | J23: 185 | K23: 200 | L23: 160 | M23: 🏆 BOOKED — T1 | N23: ✅ Booked T1 +5.9% | O23: WIN | P23: 0.058824 | Q23: T1 | R23: 30 | S23: =IFERROR(VLOOKUP(B23,SectorMap!A:B,2,0),"Chemicals") -> Chemicals | T23: =IFERROR(VLOOKUP(B23,SectorMap!A:C,3,0),"Rubber chemicals") -> Rubber chemicals | U23: 29 Nov 2025 | V23: 180
A24: 20 | B24: BSE | C24: BSE Ltd | D24: 03 Nov 2025 | E24: 2500 | F24: 2550 | G24: NSE: | H24: =IFERROR(googlefinance("NSE:BSE","price"),"–") -> – | I24: 2750 | J24: 3000 | K24: 3905 | L24: 225 | M24: 🏆 BOOKED — T3 | N24: ✅ Booked T3 +56.2% | O24: WIN | P24: 0.562 | Q24: T3 | R24: 60 | S24: =IFERROR(VLOOKUP(B24,SectorMap!A:B,2,0),"Finance") -> Finance | T24: =IFERROR(VLOOKUP(B24,SectorMap!A:C,3,0),"Volume surge") -> Volume surge | U24: 02 Jan 2026 | V24: 3905
A25: 21 | B25: MRPL | C25: MRPL | D25: 04 Nov 2025 | E25: 140 | F25: 145 | G25: NSE: | H25: =IFERROR(googlefinance("NSE:MRPL","price"),"–") -> – | I25: 167 | J25: 180 | K25: 190 | L25: 125 | M25: 🏆 BOOKED — T1 | N25: ✅ Booked T1 +19.3% | O25: WIN | P25: 0.192857 | Q25: T1 | R25: 30 | S25: =IFERROR(VLOOKUP(B25,SectorMap!A:B,2,0),"Energy") -> Energy | T25: =IFERROR(VLOOKUP(B25,SectorMap!A:C,3,0),"GRM expansion") -> GRM expansion | U25: 04 Dec 2025 | V25: 167
A26: 22 | B26: UTKARSHBNK | C26: UTKARSH BANK | D26: 07 Nov 2025 | E26: 15 | F26: 15.5 | G26: NSE: | H26: =IFERROR(googlefinance("NSE:UTKARSHBNK","price"),"–") -> – | I26: 16 | J26: 17 | K26: 18 | L26: 12.5 | M26: =IF(OR(H26="",H26="–"),"–",IFERROR(IF(H26<L26,"🔴 SL Hit",IF(AND(ISNUMBER(K26),H26>=K26),"🎯 T3 Hit — Book!",IF(AND(ISNUMBER(J26),H26>=J26),"🎯 T2 Hit — Book!",IF(AND(ISNUMBER(I26),H26>=I26),"🎯 T1 Hit — Book!",IF(AND(H26>=E26),"🟡 In/Above Buy Zone","🔻 Below Buy Zone"))))),"-")) -> – | N26: =IF(M26="🎯 T3 Hit — Book!","🏆 BOOK T3 PROFITS!",IF(M26="🎯 T2 Hit — Book!","🎯 BOOK T2 PROFITS!",IF(M26="🎯 T1 Hit — Book!","📈 BOOK T1 PROFITS!",IF(M26="🔴 SL Hit","⚠️ EXIT NOW!",IF(M26="🟡 In/Above Buy Zone","🔔 BUY NOW!","⏳ Wait"))))) -> ⏳ Wait | O26: OPEN | P26: =IF(OR(ISBLANK(H26),H26="–",NOT(ISNUMBER(H26)),E26=0),"–",(H26-E26)/E26) -> – | Q26: OPEN | R26: 202 | S26: =IFERROR(VLOOKUP(B26,SectorMap!A:B,2,0),"Banking") -> Banking | T26: =IFERROR(VLOOKUP(B26,SectorMap!A:C,3,0),"SFB expansion") -> SFB expansion | U26: Open | V26: –
A27: 23 | B27: ASIANTILES | C27: ASIAN TILES | D27: 10 Nov 2025 | E27: 60 | F27: 65 | G27: NSE: | H27: =IFERROR(googlefinance("NSE:ASIANTILES","price"),"–") -> – | I27: 70 | J27: 75 | K27: – | L27: 55 | M27: =IF(OR(H27="",H27="–"),"–",IFERROR(IF(H27<L27,"🔴 SL Hit",IF(AND(ISNUMBER(K27),H27>=K27),"🎯 T3 Hit — Book!",IF(AND(ISNUMBER(J27),H27>=J27),"🎯 T2 Hit — Book!",IF(AND(ISNUMBER(I27),H27>=I27),"🎯 T1 Hit — Book!",IF(AND(H27>=E27),"🟡 In/Above Buy Zone","🔻 Below Buy Zone"))))),"-")) -> – | N27: =IF(M27="🎯 T3 Hit — Book!","🏆 BOOK T3 PROFITS!",IF(M27="🎯 T2 Hit — Book!","🎯 BOOK T2 PROFITS!",IF(M27="🎯 T1 Hit — Book!","📈 BOOK T1 PROFITS!",IF(M27="🔴 SL Hit","⚠️ EXIT NOW!",IF(M27="🟡 In/Above Buy Zone","🔔 BUY NOW!","⏳ Wait"))))) -> ⏳ Wait | O27: OPEN | P27: =IF(OR(ISBLANK(H27),H27="–",NOT(ISNUMBER(H27)),E27=0),"–",(H27-E27)/E27) -> – | Q27: OPEN | R27: 199 | S27: =IFERROR(VLOOKUP(B27,SectorMap!A:B,2,0),"Consumer") -> Consumer | T27: =IFERROR(VLOOKUP(B27,SectorMap!A:C,3,0),"Real estate linked") -> Real estate linked | U27: Open | V27: –
A28: 24 | B28: RATNAVEER | C28: RATNAVEER | D28: 11 Nov 2025 | E28: 150 | F28: 155 | G28: NSE: | H28: =IFERROR(googlefinance("NSE:RATNAVEER","price"),"–") -> – | I28: 175 | J28: 180 | K28: 190 | L28: 135 | M28: 🏆 BOOKED — T1 | N28: ✅ Booked T1 +16.7% | O28: WIN | P28: 0.166667 | Q28: T1 | R28: 30 | S28: =IFERROR(VLOOKUP(B28,SectorMap!A:B,2,0),"Metals") -> Metals | T28: =IFERROR(VLOOKUP(B28,SectorMap!A:C,3,0),"SS tubes") -> SS tubes | U28: 11 Dec 2025 | V28: 175
A29: 25 | B29: SATIN | C29: SATIN | D29: 11 Nov 2025 | E29: 150 | F29: 152 | G29: NSE: | H29: =IFERROR(googlefinance("NSE:SATIN","price"),"–") -> – | I29: 170 | J29: 190 | K29: 210 | L29: 130 | M29: 🏆 BOOKED — T3 | N29: ✅ Booked T3 +40.0% | O29: WIN | P29: 0.4 | Q29: T3 | R29: 60 | S29: =IFERROR(VLOOKUP(B29,SectorMap!A:B,2,0),"NBFC") -> NBFC | T29: =IFERROR(VLOOKUP(B29,SectorMap!A:C,3,0),"MFI recovery") -> MFI recovery | U29: 10 Jan 2026 | V29: 210
A30: 26 | B30: PRICOLLTD | C30: PRICOL | D30: 12 Nov 2025 | E30: 550 | F30: 575 | G30: NSE: | H30: =IFERROR(googlefinance("NSE:PRICOLLTD","price"),"–") -> – | I30: 600 | J30: 625 | K30: 700 | L30: 500 | M30: 🏆 BOOKED — T1 | N30: ✅ Booked T1 +9.1% | O30: WIN | P30: 0.090909 | Q30: T1 | R30: 30 | S30: =IFERROR(VLOOKUP(B30,SectorMap!A:B,2,0),"Auto Ancillary") -> Auto Ancillary | T30: =IFERROR(VLOOKUP(B30,SectorMap!A:C,3,0),"EV content") -> EV content | U30: 12 Dec 2025 | V30: 600
A31: 27 | B31: JAMNAAUTO | C31: JAMNA AUTO | D31: 14 Nov 2025 | E31: 90 | F31: 92.5 | G31: NSE: | H31: =IFERROR(googlefinance("NSE:JAMNAAUTO","price"),"–") -> – | I31: 115 | J31: 125 | K31: 131 | L31: 85 | M31: 🏆 BOOKED — T3 | N31: ✅ Booked T3 +45.6% | O31: WIN | P31: 0.455556 | Q31: T3 | R31: 60 | S31: =IFERROR(VLOOKUP(B31,SectorMap!A:B,2,0),"Auto Ancillary") -> Auto Ancillary | T31: =IFERROR(VLOOKUP(B31,SectorMap!A:C,3,0),"CV leaf springs") -> CV leaf springs | U31: 13 Jan 2026 | V31: 131
A32: 28 | B32: PVRINOX | C32: PVR | D32: 17 Nov 2025 | E32: 1000 | F32: 1090 | G32: NSE: | H32: =IFERROR(googlefinance("NSE:PVRINOX","price"),"–") -> – | I32: 1100 | J32: 1200 | K32: 1500 | L32: 950 | M32: =IF(OR(H32="",H32="–"),"–",IFERROR(IF(H32<L32,"🔴 SL Hit",IF(AND(ISNUMBER(K32),H32>=K32),"🎯 T3 Hit — Book!",IF(AND(ISNUMBER(J32),H32>=J32),"🎯 T2 Hit — Book!",IF(AND(ISNUMBER(I32),H32>=I32),"🎯 T1 Hit — Book!",IF(AND(H32>=E32),"🟡 In/Above Buy Zone","🔻 Below Buy Zone"))))),"-")) -> – | N32: =IF(M32="🎯 T3 Hit — Book!","🏆 BOOK T3 PROFITS!",IF(M32="🎯 T2 Hit — Book!","🎯 BOOK T2 PROFITS!",IF(M32="🎯 T1 Hit — Book!","📈 BOOK T1 PROFITS!",IF(M32="🔴 SL Hit","⚠️ EXIT NOW!",IF(M32="🟡 In/Above Buy Zone","🔔 BUY NOW!","⏳ Wait"))))) -> ⏳ Wait | O32: OPEN | P32: =IF(OR(ISBLANK(H32),H32="–",NOT(ISNUMBER(H32)),E32=0),"–",(H32-E32)/E32) -> – | Q32: OPEN | R32: 192 | S32: =IFERROR(VLOOKUP(B32,SectorMap!A:B,2,0),"Media") -> Media | T32: =IFERROR(VLOOKUP(B32,SectorMap!A:C,3,0),"Box office revival") -> Box office revival | U32: Open | V32: –
A33: 29 | B33: GRASIM | C33: GRASIM | D33: 17 Nov 2025 | E33: 2750 | F33: 2785 | G33: NSE: | H33: =IFERROR(googlefinance("NSE:GRASIM","price"),"–") -> – | I33: 2850 | J33: 2950 | K33: 3250 | L33: 2500 | M33: 🏆 BOOKED — T2 | N33: ✅ Booked T2 +7.3% | O33: WIN | P33: 0.072727 | Q33: T2 | R33: 45 | S33: =IFERROR(VLOOKUP(B33,SectorMap!A:B,2,0),"Industrials") -> Industrials | T33: =IFERROR(VLOOKUP(B33,SectorMap!A:C,3,0),"Paint + cement") -> Paint + cement | U33: 01 Jan 2026 | V33: 2950
A34: 30 | B34: TITAN | C34: TITAN | D34: 18 Nov 2025 | E34: 3800 | F34: 3850 | G34: NSE: | H34: =IFERROR(googlefinance("NSE:TITAN","price"),"–") -> – | I34: 4200 | J34: 4400 | K34: 4500 | L34: 450 | M34: 🏆 BOOKED — T3 | N34: ✅ Booked T3 +18.4% | O34: WIN | P34: 0.184211 | Q34: T3 | R34: 60 | S34: =IFERROR(VLOOKUP(B34,SectorMap!A:B,2,0),"Consumer") -> Consumer | T34: =IFERROR(VLOOKUP(B34,SectorMap!A:C,3,0),"Jewellery demand") -> Jewellery demand | U34: 17 Jan 2026 | V34: 4500
A35: 31 | B35: BBTC | C35: BBTC | D35: 18 Nov 2025 | E35: 1800 | F35: 1850 | G35: NSE: | H35: =IFERROR(googlefinance("NSE:BBTC","price"),"–") -> – | I35: 2000 | J35: 2100 | K35: – | L35: 1600 | M35: 🔴 SL EXIT | N35: ⚠️ SL Exit -11.1% | O35: LOSS | P35: -0.111111 | Q35: SL | R35: 15 | S35: =IFERROR(VLOOKUP(B35,SectorMap!A:B,2,0),"Agri") -> Agri | T35: =IFERROR(VLOOKUP(B35,SectorMap!A:C,3,0),"Plantation play") -> Plantation play | U35: 03 Dec 2025 | V35: 1600
A36: 32 | B36: AWL | C36: AWL | D36: 19 Nov 2025 | E36: 270 | F36: 275 | G36: NSE: | H36: =IFERROR(googlefinance("NSE:AWL","price"),"–") -> – | I36: 300 | J36: – | K36: – | L36: 260 | M36: 🔴 SL EXIT | N36: ⚠️ SL Exit -3.7% | O36: LOSS | P36: -0.037037 | Q36: SL | R36: 15 | S36: =IFERROR(VLOOKUP(B36,SectorMap!A:B,2,0),"FMCG") -> FMCG | T36: =IFERROR(VLOOKUP(B36,SectorMap!A:C,3,0),"Edible oil") -> Edible oil | U36: 04 Dec 2025 | V36: 260
A37: 33 | B37: POLYMED | C37: POLYMED | D37: 24 Nov 2025 | E37: 1750 | F37: 1850 | G37: NSE: | H37: =IFERROR(googlefinance("NSE:POLYMED","price"),"–") -> – | I37: 2000 | J37: 2200 | K37: 2400 | L37: 1600 | M37: 🏆 BOOKED — T4 | N37: ✅ Booked T4 +0.0% | O37: WIN | P37: 0 | Q37: T4 | R37: 35 | S37: =IFERROR(VLOOKUP(B37,SectorMap!A:B,2,0),"Healthcare") -> Healthcare | T37: =IFERROR(VLOOKUP(B37,SectorMap!A:C,3,0),"Medical devices") -> Medical devices | U37: 29 Dec 2025 | V37: –
A38: 34 | B38: YATHARTH | C38: YATHARTH | D38: 24 Nov 2025 | E38: 650 | F38: 700 | G38: NSE: | H38: =IFERROR(googlefinance("NSE:YATHARTH","price"),"–") -> – | I38: 850 | J38: 950 | K38: 1100 | L38: 600 | M38: 🏆 BOOKED — T1 | N38: ✅ Booked T1 +30.8% | O38: WIN | P38: 0.307692 | Q38: T1 | R38: 30 | S38: =IFERROR(VLOOKUP(B38,SectorMap!A:B,2,0),"Healthcare") -> Healthcare | T38: =IFERROR(VLOOKUP(B38,SectorMap!A:C,3,0),"Hospital growth") -> Hospital growth | U38: 24 Dec 2025 | V38: 850
A39: 35 | B39: GMRAIRPORT | C39: GMR AIRPORTS | D39: 24 Nov 2025 | E39: 94 | F39: 95 | G39: NSE: | H39: =IFERROR(googlefinance("NSE:GMRAIRPORT","price"),"–") -> – | I39: 105 | J39: 110 | K39: 115 | L39: 90 | M39: 🏆 BOOKED — T1 | N39: ✅ Booked T1 +11.7% | O39: WIN | P39: 0.117021 | Q39: T1 | R39: 30 | S39: =IFERROR(VLOOKUP(B39,SectorMap!A:B,2,0),"Infrastructure") -> Infrastructure | T39: =IFERROR(VLOOKUP(B39,SectorMap!A:C,3,0),"Aviation infra") -> Aviation infra | U39: 24 Dec 2025 | V39: 105
A40: 36 | B40: GRSE | C40: GRSE | D40: 27 Nov 2025 | E40: 2800 | F40: 2840 | G40: NSE: | H40: =IFERROR(googlefinance("NSE:GRSE","price"),"–") -> – | I40: 3000 | J40: 3200 | K40: – | L40: 2750 | M40: 🏆 BOOKED — T1 | N40: ✅ Booked T1 +7.1% | O40: WIN | P40: 0.071429 | Q40: T1 | R40: 30 | S40: =IFERROR(VLOOKUP(B40,SectorMap!A:B,2,0),"Defence") -> Defence | T40: =IFERROR(VLOOKUP(B40,SectorMap!A:C,3,0),"Naval orders") -> Naval orders | U40: 27 Dec 2025 | V40: 3000
A41: 37 | B41: PPLPHARMA | C41: PPL PHARMA | D41: 28 Nov 2025 | E41: 180 | F41: 190 | G41: NSE: | H41: =IFERROR(googlefinance("NSE:PPLPHARMA","price"),"–") -> – | I41: 200 | J41: 210 | K41: 240 | L41: 178 | M41: =IF(OR(H41="",H41="–"),"–",IFERROR(IF(H41<L41,"🔴 SL Hit",IF(AND(ISNUMBER(K41),H41>=K41),"🎯 T3 Hit — Book!",IF(AND(ISNUMBER(J41),H41>=J41),"🎯 T2 Hit — Book!",IF(AND(ISNUMBER(I41),H41>=I41),"🎯 T1 Hit — Book!",IF(AND(H41>=E41),"🟡 In/Above Buy Zone","🔻 Below Buy Zone"))))),"-")) -> – | N41: =IF(M41="🎯 T3 Hit — Book!","🏆 BOOK T3 PROFITS!",IF(M41="🎯 T2 Hit — Book!","🎯 BOOK T2 PROFITS!",IF(M41="🎯 T1 Hit — Book!","📈 BOOK T1 PROFITS!",IF(M41="🔴 SL Hit","⚠️ EXIT NOW!",IF(M41="🟡 In/Above Buy Zone","🔔 BUY NOW!","⏳ Wait"))))) -> ⏳ Wait | O41: OPEN | P41: =IF(OR(ISBLANK(H41),H41="–",NOT(ISNUMBER(H41)),E41=0),"–",(H41-E41)/E41) -> – | Q41: OPEN | R41: 181 | S41: =IFERROR(VLOOKUP(B41,SectorMap!A:B,2,0),"Pharma") -> Pharma | T41: =IFERROR(VLOOKUP(B41,SectorMap!A:C,3,0),"Generic exports") -> Generic exports | U41: Open | V41: –
...

Sheet 🔔 Alert Board
A1: 🔔 LIVE ALERT BOARD — Open trades only · Status auto-updates · Prices live via GOOGLEFINANCE
A2: This sheet shows ONLY active open trades. All data auto-pulled from Trade Tracker. Never edit this sheet manually.
A4: 🟡 24 ACTIVE OPEN TRADES — Awaiting target or SL
A5: # | B5: Symbol | C5: Company | D5: Entry Date | E5: Entry ₹ | F5: T1 ₹ | G5: T2 ₹ | H5: T3 ₹ | I5: SL ₹ | J5: Live Status
A6: 1 | B6: NBCC | C6: NBCC | D6: 24 Oct 2025 | E6: 100 | F6: 120 | G6: 125 | H6: – | I6: 95 | J6: ='Trade Tracker'!M12 -> –
A7: 2 | B7: SAGILITY | C7: SAGILITY | D7: 29 Oct 2025 | E7: 45 | F7: 50 | G7: 55 | H7: 60 | I7: 40 | J7: ='Trade Tracker'!M19 -> –
A8: 3 | B8: CANFINHOME | C8: CAN FIN HOMES | D8: 29 Oct 2025 | E8: 850 | F8: 890 | G8: 1000 | H8: – | I8: 800 | J8: ='Trade Tracker'!M20 -> –
A9: 4 | B9: DLINKINDIA | C9: DLINK | D9: 30 Oct 2025 | E9: 460 | F9: 525 | G9: 550 | H9: 600 | I9: 425 | J9: ='Trade Tracker'!M22 -> –
A10: 5 | B10: UTKARSHBNK | C10: UTKARSH BANK | D10: 07 Nov 2025 | E10: 15 | F10: 16 | G10: 17 | H10: 18 | I10: 12.5 | J10: ='Trade Tracker'!M26 -> –
A11: 6 | B11: ASIANTILES | C11: ASIAN TILES | D11: 10 Nov 2025 | E11: 60 | F11: 70 | G11: 75 | H11: – | I11: 55 | J11: ='Trade Tracker'!M27 -> –
A12: 7 | B12: PVRINOX | C12: PVR | D12: 17 Nov 2025 | E12: 1000 | F12: 1100 | G12: 1200 | H12: 1500 | I12: 950 | J12: ='Trade Tracker'!M32 -> –
A13: 8 | B13: PPLPHARMA | C13: PPL PHARMA | D13: 28 Nov 2025 | E13: 180 | F13: 200 | G13: 210 | H13: 240 | I13: 178 | J13: ='Trade Tracker'!M41 -> –
A14: 9 | B14: PETRONET | C14: PETRONET | D14: 28 Dec 2025 | E14: 275 | F14: 320 | G14: 350 | H14: – | I14: 250 | J14: ='Trade Tracker'!M51 -> –
A15: 10 | B15: MAMATA | C15: MAMATA | D15: 01 Jan 2026 | E15: 430 | F15: 460 | G15: 475 | H15: 500 | I15: 400 | J15: ='Trade Tracker'!M54 -> –
A16: 11 | B16: NORTHARC | C16: NORTHERN ARC | D16: 06 Jan 2026 | E16: 250 | F16: 275 | G16: 290 | H16: 300 | I16: 225 | J16: ='Trade Tracker'!M58 -> –
A17: 12 | B17: TATATECH | C17: TATA TECH | D17: 07 Jan 2026 | E17: 640 | F17: 700 | G17: 740 | H17: 800 | I17: 625 | J17: ='Trade Tracker'!M64 -> –
A18: 13 | B18: BIOCON | C18: BIOCON | D18: 16 Jan 2026 | E18: 360 | F18: 380 | G18: 395 | H18: 420 | I18: 325 | J18: ='Trade Tracker'!M74 -> –
A19: 14 | B19: INDHOTEL | C19: INDIAN HOTELS | D19: 16 Jan 2026 | E19: 645 | F19: 675 | G19: 725 | H19: – | I19: 600 | J19: ='Trade Tracker'!M75 -> –
A20: 15 | B20: COLPAL | C20: Colgate-Palmolive | D20: 25 Jan 2026 | E20: 2150 | F20: 2200 | G20: 2300 | H20: 2400 | I20: 2025 | J20: ='Trade Tracker'!M78 -> –
A21: 16 | B21: FORTIS | C21: Fortis Healthcare | D21: 28 Jan 2026 | E21: 950 | F21: 1000 | G21: 1050 | H21: 1200 | I21: 900 | J21: ='Trade Tracker'!M84 -> –
A22: 17 | B22: BEL | C22: BEL | D22: 01 Feb 2026 | E22: 457 | F22: 480 | G22: 500 | H22: 525 | I22: 430 | J22: ='Trade Tracker'!M88 -> –
A23: 18 | B23: AJANTPHARM | C23: Ajanta Pharma | D23: 10 Feb 2026 | E23: 3000 | F23: 3300 | G23: 3800 | H23: 4000 | I23: 2800 | J23: ='Trade Tracker'!M101 -> –
A24: 19 | B24: CHAMBLFERT | C24: Chambal Fertilisers | D24: 02 Mar 2026 | E24: 440 | F24: 500 | G24: 550 | H24: 600 | I24: 385 | J24: ='Trade Tracker'!M115 -> –
A25: 20 | B25: EMBDL | C25: EMBDL | D25: 08 Mar 2026 | E25: 40 | F25: 60 | G25: 100 | H25: 150 | I25: 35 | J25: ='Trade Tracker'!M120 -> –
A26: 21 | B26: LAURUSLABS | C26: Laurus Labs | D26: 20 Mar 2026 | E26: 1000 | F26: 1175 | G26: 1200 | H26: 1225 | I26: 975 | J26: ='Trade Tracker'!M129 -> –
A27: 22 | B27: UTIAMC | C27: UTI AMC | D27: 22 Mar 2026 | E27: 900 | F27: 1250 | G27: 1350 | H27: 1500 | I27: 700 | J27: ='Trade Tracker'!M131 -> –
A28: 23 | B28: BIRLACABLE | C28: Birla Cable | D28: 23 Mar 2026 | E28: 156 | F28: 166 | G28: 172 | H28: 180 | I28: 155 | J28: ='Trade Tracker'!M133 -> –
A29: 24 | B29: ADANIENSOL | C29: Adani Energy Solution | D29: 01 Apr 2026 | E29: 1150 | F29: 1500 | G29: 1750 | H29: 2000 | I29: 600 | J29: ='Trade Tracker'!M137 -> –
A30: 25 | B30: ← Add ticker | E30: – | F30: – | G30: – | H30: – | I30: – | J30: ='Trade Tracker'!M138 -> –
A31: 26 | B31: ← Add ticker | E31: – | F31: – | G31: – | H31: – | I31: – | J31: ='Trade Tracker'!M139 -> –
A32: 27 | B32: ← Add ticker | E32: – | F32: – | G32: – | H32: – | I32: – | J32: ='Trade Tracker'!M140 -> –
A33: 28 | B33: ← Add ticker | E33: – | F33: – | G33: – | H33: – | I33: – | J33: ='Trade Tracker'!M141 -> –
A34: 29 | B34: ← Add ticker | E34: – | F34: – | G34: – | H34: – | I34: – | J34: ='Trade Tracker'!M142 -> –
A35: 30 | B35: ← Add ticker | E35: – | F35: – | G35: – | H35: – | I35: – | J35: ='Trade Tracker'!M143 -> –
A36: 31 | B36: ← Add ticker | E36: – | F36: – | G36: – | H36: – | I36: – | J36: ='Trade Tracker'!M144 -> –
A37: 32 | B37: ← Add ticker | E37: – | F37: – | G37: – | H37: – | I37: – | J37: ='Trade Tracker'!M145 -> –
A38: 33 | B38: ← Add ticker | E38: – | F38: – | G38: – | H38: – | I38: – | J38: ='Trade Tracker'!M146 -> –
A39: 34 | B39: ← Add ticker | E39: – | F39: – | G39: – | H39: – | I39: – | J39: ='Trade Tracker'!M147 -> –
A40: 35 | B40: ← Add ticker | E40: – | F40: – | G40: – | H40: – | I40: – | J40: ='Trade Tracker'!M148 -> –
A41: 36 | B41: ← Add ticker | E41: – | F41: – | G41: – | H41: – | I41: – | J41: ='Trade Tracker'!M149 -> –
...

Sheet Sector Analysis
A1: 🏭 SECTOR ANALYSIS — All figures auto-pull from Trade Tracker
A3: Sector | B3: Total | C3: Wins | D3: Losses | E3: Open | F3: Win Rate | G3: Avg Win % | H3: Avg Loss % | I3: Best Trade
A4: AMC | B4: 3 | C4: 2 | D4: 0 | E4: 1 | F4: 1 | G4: 0.244701 | H4: 0 | I4: 0.333333
A5: Agri | B5: 2 | C5: 0 | D5: 2 | E5: 0 | F5: 0 | G5: 0 | H5: -0.0805555 | I5: 0
A6: Auto | B6: 8 | C6: 6 | D6: 2 | E6: 0 | F6: 0.75 | G6: 0.1652725 | H6: -0.045547 | I6: 0.217143
A7: Auto Ancillary | B7: 2 | C7: 2 | D7: 0 | E7: 0 | F7: 1 | G7: 0.2732325 | H7: 0 | I7: 0.455556
A8: Banking | B8: 8 | C8: 4 | D8: 3 | E8: 1 | F8: 0.57142857 | G8: 0.22294275 | H8: -0.055743667 | I8: 0.290323
A9: Broking | B9: 1 | C9: 1 | D9: 0 | E9: 0 | F9: 1 | G9: 0.3 | H9: 0 | I9: 0.3
A10: Cement | B10: 1 | C10: 0 | D10: 1 | E10: 0 | F10: 0 | G10: 0 | H10: -0.063291 | I10: 0
A11: Chemicals | B11: 4 | C11: 1 | D11: 2 | E11: 1 | F11: 0.33333333 | G11: 0.058824 | H11: -0.0460785 | I11: 0.058824
A12: Consumer | B12: 7 | C12: 6 | D12: 0 | E12: 1 | F12: 1 | G12: 0.14129933 | H12: 0 | I12: 0.226027
A13: Defence | B13: 6 | C13: 5 | D13: 0 | E13: 1 | F13: 1 | G13: 0.4867712 | H13: 0 | I13: 1.653061
A14: Education | B14: 1 | C14: 1 | D14: 0 | E14: 0 | F14: 1 | G14: 0.333333 | H14: 0 | I14: 0.333333
A15: Energy | B15: 7 | C15: 3 | D15: 3 | E15: 1 | F15: 0.5 | G15: 0.186508 | H15: -0.039825333 | I15: 0.2
... A34: TOTAL | B34: 133 | C34: 84 | D34: 25 | E34: 24 | F34: 0.7706422 | G34: 0.24018344 | H34: -0.04299296 | I34: 1.653061

Sheet 📋 Setup Guide
A1: 📋 COMPLETE SETUP GUIDE — How everything works & how to keep it live
B3: HOW TO ADD A NEW TRADE
B4: 1. Go to Trade Tracker tab → scroll to bottom → find blank row with '← Add ticker'
B5: 2. Col B: Type NSE ticker EXACTLY (e.g. TATAMOTORS, RELIANCE, HDFCBANK)
B6: 3. Col S (Sector) & Col T (Notes) will AUTO-FILL via VLOOKUP from SectorMap sheet
B7: 4. Col H (CMP) will AUTO-FETCH live price via GOOGLEFINANCE — no manual entry needed
B8: 5. Fill: Rec Date (DD Mon YYYY), Buy Low, Buy High, T1, T2, T3, Stop Loss
B9: 6. Leave Result as OPEN — Col M status auto-updates with live price
B11: HOW TO BOOK A TRADE (when target hit)
B12: 1. Change Col O (Result) from OPEN → WIN
B13: 2. Change Col Q (Best Target) to T1 / T2 / T3 (whichever was hit)
B14: 3. The % return auto-locks based on the target price — never changes again
B15: 4. All dashboards (Performance, Sector, Portfolio) instantly update
... B48: Change admin password: find ADMIN_PASSWORD = and change the value

Sheet 💰 Portfolio Sim
A1: 💰 PORTFOLIO SIMULATOR — ₹10L invested, 5% per trade (compounds)
A3: Initial | B3: Final Value | C3: Our Return | D3: Nifty Same Period | E3: Extra vs Nifty | F3: Win Rate
A4: ₹1,000,000 | B4: ₹2,565,184 | C4: +156.5% | D4: -4.2% | E4: ₹1,607,672 | F4: 77.1%
A6: Month | B6: Our Portfolio | C6: Nifty 50 | D6: Our Return % | E6: Nifty Return %
A7: 2024-09 | B7: 1000000 | C7: 1000000 | D7: 0 | E7: 0
A8: 2024-10 | B8: 1728752 | C8: 963483 | D8: 0.729 | E8: -0.037
A9: 2024-11 | B9: 2405685 | C9: 912234 | D9: 1.406 | E9: -0.088
A10: 2024-12 | B10: 2405685 | C10: 923128 | D10: 1.406 | E10: -0.077
A11: 2025-01 | B11: 2405685 | C11: 916576 | D11: 1.406 | E11: -0.083
A12: 2025-02 | B12: 2405685 | C12: 897930 | D12: 1.406 | E12: -0.102
A13: 2025-03 | B13: 2405685 | C13: 865909 | D13: 1.406 | E13: -0.134
A14: 2025-04 | B14: 2405685 | C14: 911731 | D14: 1.406 | E14: -0.088
A15: 2025-05 | B15: 2405685 | C15: 931889 | D15: 1.406 | E15: -0.068
A16: 2025-06 | B16: 2405685 | C16: 935688 | D16: 1.406 | E16: -0.064
A17: 2025-07 | B17: 2405685 | C17: 962785 | D17: 1.406 | E17: -0.037
A18: 2025-08 | B18: 2405685 | C18: 978252 | D18: 1.406 | E18: -0.022
... A27: 2026-05 | B27: 2565184 | C27: 957513 | D27: 1.565 | E27: -0.042

Sheet Apps Script Code
A1: 📜 APPS SCRIPT — Paste this in Google Sheets → Extensions → Apps Script → Run once
B3: // JAIN CAPITAL — Google Apps Script
B4: // Paste this entire script in: Google Sheets → Extensions → Apps Script → Save → Run deployAsWebApp()
B5: // This publishes your Trade Tracker as a live JSON that the website reads
B7: function doGet(e) {
B8: var ss = SpreadsheetApp.getActiveSpreadsheet();
B9: var ws = ss.getSheetByName('Trade Tracker');
B10: var data = ws.getDataRange().getValues();
B11: var headers = data[3]; // Row 4 = headers
B12: var trades = [];
B13: for (var i = 4; i < data.length; i++) {
B14: var row = data[i];
B15: if (!row[1] || row[1] === '' || row[1] === '← Add ticker') continue;
... B34: // 4. Paste that URL in index.html where you see: GOOGLE_SHEETS_JSON_URL
